Workbook

Sheet Лист1
A1: Учащиеся | B1: Математика | C1: Русский | D1: Информатика | E1: Средне Орифметическое | F1: Статус
A2: Студент1 | B2: 40 | C2: 70 | D2: 40 | E2: =AVERAGE(B2:D2) -> 50 | F2: =IF(E2>60,"проход","непроход") -> непроход
A3: Студент2 | B3: 60 | C3: 50 | D3: 60 | E3: =AVERAGE(B3:D3) -> 56.666667 | F3: =IF(E3>60,"проход","непроход") -> непроход
A4: Студент3 | B4: 60 | C4: 70 | D4: 60 | E4: =AVERAGE(B4:D4) -> 63.333333 | F4: =IF(E4>60,"проход","непроход") -> проход
A5: Студент4 | B5: 70 | C5: 60 | D5: 70 | E5: =AVERAGE(B5:D5) -> 66.666667 | F5: =IF(E5>60,"проход","непроход") -> проход
A6: Студент5 | B6: 50 | C6: 40 | D6: 50 | E6: =AVERAGE(B6:D6) -> 46.666667 | F6: =IF(E6>60,"проход","непроход") -> непроход
A7: Студент6 | B7: 50 | C7: 70 | D7: 30 | E7: =AVERAGE(B7:D7) -> 50 | F7: =IF(E7>60,"проход","непроход") -> непроход
A8: Студент7 | B8: 70 | C8: 70 | D8: 50 | E8: =AVERAGE(B8:D8) -> 63.333333 | F8: =IF(E8>60,"проход","непроход") -> проход
A9: Студент8 | B9: 70 | C9: 60 | D9: 70 | E9: =AVERAGE(B9:D9) -> 66.666667 | F9: =IF(E9>60,"проход","непроход") -> проход
A10: Студент9 | B10: 70 | C10: 30 | D10: 40 | E10: =AVERAGE(B10:D10) -> 46.666667 | F10: =IF(E10>60,"проход","непроход") -> непроход
A11: Студент10 | B11: 70 | C11: 40 | D11: 60 | E11: =AVERAGE(B11:D11) -> 56.666667 | F11: =IF(E11>60,"проход","непроход") -> непроход
A12: Ср. знач. по предмету | B12: =AVERAGE(B2:B11) -> 61 | C12: =AVERAGE(C2:C11) -> 56 | D12: =AVERAGE(D2:D11) -> 53

Sheet Лист6
A1: Ведомость вступительных
B2: Проходной бал | C2: 13
A3: № п/п | B3: Фамилия | C3: Математика | D3: Русский | E3: Иностранный | F3: Сумма | G3: Зачислен
A4: 1 | B4: Антонов | C4: 4 | D4: 4 | E4: 5 | F4: =SUM(C4:E4) -> 13 | G4: =IF(F4>=$C$2,"зачислен","незачислен") -> зачислен
A5: 2 | B5: Акулова | C5: 3 | D5: 3 | E5: 4 | F5: =SUM(C5:E5) -> 10 | G5: =IF(F5>=$C$2,"зачислен","незачислен") -> незачислен
A6: 3 | B6: Борисов | C6: 5 | D6: 4 | E6: 3 | F6: =SUM(C6:E6) -> 12 | G6: =IF(F6>=$C$2,"зачислен","незачислен") -> незачислен
A7: 4 | B7: Воробьёва | C7: 5 | D7: 5 | E7: 4 | F7: =SUM(C7:E7) -> 14 | G7: =IF(F7>=$C$2,"зачислен","незачислен") -> зачислен
A8: 5 | B8: Григорьев | C8: 3 | D8: 5 | E8: 5 | F8: =SUM(C8:E8) -> 13 | G8: =IF(F8>=$C$2,"зачислен","незачислен") -> зачислен
A9: 6 | B9: Григорьева | C9: 4 | D9: 4 | E9: 4 | F9: =SUM(C9:E9) -> 12 | G9: =IF(F9>=$C$2,"зачислен","незачислен") -> незачислен
A10: 7 | B10: Сапожников | C10: 5 | D10: 3 | E10: 5 | F10: =SUM(C10:E10) -> 13 | G10: =IF(F10>=$C$2,"зачислен","незачислен") -> зачислен

Sheet Расчёт цен
A1: Мебель для офиса
A2: №п/п | B2: Наименование товара | C2: Цена | D2: Налог с продаж | E2: Сумма
A3: 1 | B3: шкаф | C3: 9800 | D3: =C3*'Налог с продаж'!$C$1 -> 490 | E3: =SUM(C3:D3) -> 10290
A4: 2 | B4: стол письменный | C4: 5400 | D4: =C4*'Налог с продаж'!$C$1 -> 270 | E4: =SUM(C4:D4) -> 5670
A5: 3 | B5: кресло | C5: 3750 | D5: =C5*'Налог с продаж'!$C$1 -> 187.5 | E5: =SUM(C5:D5) -> 3937.5
A6: 4 | B6: стол компьютерный | C6: 2850 | D6: =C6*'Налог с продаж'!$C$1 -> 142.5 | E6: =SUM(C6:D6) -> 2992.5
A7: 5 | B7: стул | C7: 2800 | D7: =C7*'Налог с продаж'!$C$1 -> 140 | E7: =SUM(C7:D7) -> 2940
D8: Итого: | E8: =SUM(E3:E7) -> 25830

Sheet Числа
A1: =TODAY() -> 46174
A3: 25 | B3: -61 | C3: 0 | D3: -82 | E3: 18 | F3: -11 | G3: 0 | H3: 30 | I3: 15 | J3: -31 | K3: 0 | L3: -58 | M3: 22
A5: общее количество чисел | K5: =COUNT(A3:M3) -> 13
A6: количество положительных чисел | K6: =COUNTIF(A3:M3,">0") -> 5
A7: количество отрицательных чисел | K7: =COUNTIF(A3:M3,"<0") -> 5
A8: количество нулей | K8: =COUNTIF(A3:M3,"=0") -> 3
A9: максимальное значение | K9: =MAX(A3:M3) -> 30
A10: минимальное значение | K10: =MIN(A3:M3) -> -82
A11: среднее значение | K11: =AVERAGE(A3:M3) -> -10.230769
A12: сумма всех чисел | K12: =SUM(A3:M3) -> -133
A13: сумма положительных чисел | K13: =SUMIF(A3:M3,">0") -> 110
A14: сумма отрицательных чисел | K14: =SUMIF(A3:M3,"<0") -> -243

Sheet Налог с продаж
B1: Налог с продаж | C1: 0.05

Sheet Банк
A1: Индивидуальные вклады коммерческого банка
A2: дата | B2: 46079
A3: время | B3: 0.40972222
A4: №п/п | B4: Фамилия вкладчика | C4: Сумма вклада, $ США | D4: Доля общего вклада, %
A5: 1 | B5: Петров | C5: 50880.95 | D5: =C5/$C$11 -> 0.39852625
A6: 2 | B6: Горелов | C6: 25690.39 | D6: =C6/$C$11 -> 0.20122059
A7: 3 | B7: Абелян | C7: 19830.41 | D7: =C7/$C$11 -> 0.15532216
A8: 4 | B8: Лукашенко | C8: 14920.18 | D8: =C8/$C$11 -> 0.11686266
A9: 5 | B9: Абрамов | C9: 10520.28 | D9: =C9/$C$11 -> 0.082400343
A10: 6 | B10: Михайлов | C10: 5830.56 | D10: =C10/$C$11 -> 0.045668
B11: Итого: | C11: =SUM(C5:C10) -> 127672.77

Sheet Диаграма
A1: Индивидуальные вклады коммерческого банка
A2: дата | B2: 46079
A3: время | B3: 0.40972222
A4: №п/п | B4: Фамилия вкладчика | C4: Сумма вклада, $ США | D4: Доля общего вклада, %
A5: 1 | B5: Петров | C5: 50880.95 | D5: =C5/$C$11 -> 0.39852625
A6: 2 | B6: Горелов | C6: 25690.39 | D6: =C6/$C$11 -> 0.20122059
A7: 3 | B7: Абелян | C7: 19830.41 | D7: =C7/$C$11 -> 0.15532216
A8: 4 | B8: Лукашенко | C8: 14920.18 | D8: =C8/$C$11 -> 0.11686266
A9: 5 | B9: Абрамов | C9: 10520.28 | D9: =C9/$C$11 -> 0.082400343
A10: 6 | B10: Михайлов | C10: 5830.56 | D10: =C10/$C$11 -> 0.045668
B11: Итого: | C11: =SUM(C5:C10) -> 127672.77

Sheet Диаграмма
A1: Мебель для офиса
A2: №п/п | B2: Наименование товара | C2: Цена | D2: Налог с продаж | E2: Сумма
A3: 1 | B3: шкаф | C3: 9800 | D3: =C3*'Налог с продаж'!$C$1 -> 490 | E3: =SUM(C3:D3) -> 10290
A4: 2 | B4: стол письменный | C4: 5400 | D4: =C4*'Налог с продаж'!$C$1 -> 270 | E4: =SUM(C4:D4) -> 5670
A5: 3 | B5: кресло | C5: 3750 | D5: =C5*'Налог с продаж'!$C$1 -> 187.5 | E5: =SUM(C5:D5) -> 3937.5
A6: 4 | B6: стол компьютерный | C6: 2850 | D6: =C6*'Налог с продаж'!$C$1 -> 142.5 | E6: =SUM(C6:D6) -> 2992.5
A7: 5 | B7: стул | C7: 2800 | D7: =C7*'Налог с продаж'!$C$1 -> 140 | E7: =SUM(C7:D7) -> 2940
D8: Итого: | E8: =SUM(E3:E7) -> 25830

Sheet График
A1: x | B1: y
A2: -5 | B2: =SIN(A2) -> 0.95892427
A3: -4.5 | B3: =SIN(A3) -> 0.97753012
A4: -4 | B4: =SIN(A4) -> 0.7568025
A5: -3.5 | B5: =SIN(A5) -> 0.35078323
A6: -3 | B6: =SIN(A6) -> -0.14112001
A7: -2.5 | B7: =SIN(A7) -> -0.59847214
A8: -2 | B8: =SIN(A8) -> -0.90929743
A9: -1.5 | B9: =SIN(A9) -> -0.99749499
A10: -1 | B10: =SIN(A10) -> -0.84147098
A11: -0.5 | B11: =SIN(A11) -> -0.47942554
A12: 0 | B12: =SIN(A12) -> 0
A13: 0.5 | B13: =SIN(A13) -> 0.47942554
... A22: 5 | B22: =SIN(A22) -> -0.95892427

Sheet Изменение биоритмов человека
A1: Симаков Владислав | B1: Фамилия, имя | D1: Периоды
A2: 39721 | B2: дата рождения | D2: 23 | E2: дня | F2: физической
A3: =TODAY() -> 46174 | B3: текущая дата | D3: 28 | E3: дней | F3: эмоциональной
A4: =A3-A2 -> 6453 | B4: прожито дней | D4: 33 | E4: дня | F4: интелектуальной
A5: Таблица биоритмов
A6: даты иследований | B6: прожито дней | C6: физической | D6: эмоциональной | E6: интелектуальной
A7: =A3 -> 46174 | B7: =A4 -> 6453 | C7: =SIN((2*PI()*A7-B7)/$D$2) -> -0.52583651 | D7: =SIN((2*PI()*A7-B7)/$D$3) -> 0.6281887 | E7: =SIN((2*PI()*A7-B7)/$D$4) -> 0.53633345
A8: =A7+1 -> 46175 | B8: =B7+1 -> 6454 | C8: =SIN((2*PI()*A8-B8)/$D$2) -> -0.31835582 | D8: =SIN((2*PI()*A8-B8)/$D$3) -> 0.47110039 | E8: =SIN((2*PI()*A8-B8)/$D$4) -> 0.66402074
A9: =A8+1 -> 46176 | B9: =B8+1 -> 6455 | C9: =SIN((2*PI()*A9-B9)/$D$2) -> -0.094151191 | D9: =SIN((2*PI()*A9-B9)/$D$3) -> 0.29728962 | E9: =SIN((2*PI()*A9-B9)/$D$4) -> 0.77472491
A10: =A9+1 -> 46177 | B10: =B9+1 -> 6456 | C10: =SIN((2*PI()*A10-B10)/$D$2) -> 0.1349994 | D10: =SIN((2*PI()*A10-B10)/$D$3) -> 0.11292608 | E10: =SIN((2*PI()*A10-B10)/$D$4) -> 0.86561455
A11: =A10+1 -> 46178 | B11: =B10+1 -> 6457 | C11: =SIN((2*PI()*A11-B11)/$D$2) -> 0.35705818 | D11: =SIN((2*PI()*A11-B11)/$D$3) -> -0.075445948 | E11: =SIN((2*PI()*A11-B11)/$D$4) -> 0.93436507
A12: =A11+1 -> 46179 | B12: =B11+1 -> 6458 | C12: =SIN((2*PI()*A12-B12)/$D$2) -> 0.56035991 | D12: =SIN((2*PI()*A12-B12)/$D$3) -> -0.26113991 | E12: =SIN((2*PI()*A12-B12)/$D$4) -> 0.97921808
A13: =A12+1 -> 46180 | B13: =B12+1 -> 6459 | C13: =SIN((2*PI()*A13-B13)/$D$2) -> 0.7342247 | D13: =SIN((2*PI()*A13-B13)/$D$3) -> -0.43756428 | E13: =SIN((2*PI()*A13-B13)/$D$4) -> 0.99902642
A14: =A13+1 -> 46181 | B14: =B13+1 -> 6460 | C14: =SIN((2*PI()*A14-B14)/$D$2) -> 0.86951905 | D14: =SIN((2*PI()*A14-B14)/$D$3) -> -0.59845662 | E14: =SIN((2*PI()*A14-B14)/$D$4) -> 0.99328345
A15: =A14+1 -> 46182 | B15: =B14+1 -> 6461 | C15: =SIN((2*PI()*A15-B15)/$D$2) -> 0.95913565 | D15: =SIN((2*PI()*A15-B15)/$D$3) -> -0.73810578 | E15: =SIN((2*PI()*A15-B15)/$D$4) -> 0.96213607
A16: =A15+1 -> 46183 | B16: =B15+1 -> 6462 | C16: =SIN((2*PI()*A16-B16)/$D$2) -> 0.99836674 | D16: =SIN((2*PI()*A16-B16)/$D$3) -> -0.85155469 | E16: =SIN((2*PI()*A16-B16)/$D$4) -> 0.90638091
A17: =A16+1 -> 46184 | B17: =B16+1 -> 6463 | C17: =SIN((2*PI()*A17-B17)/$D$2) -> 0.98515144 | D17: =SIN((2*PI()*A17-B17)/$D$3) -> -0.93477631 | E17: =SIN((2*PI()*A17-B17)/$D$4) -> 0.82744397
A18: =A17+1 -> 46185 | B18: =B17+1 -> 6464 | C18: =SIN((2*PI()*A18-B18)/$D$2) -> 0.92018396 | D18: =SIN((2*PI()*A18-B18)/$D$3) -> -0.98481654 | E18: =SIN((2*PI()*A18-B18)/$D$4) -> 0.72734416
A19: =A18+1 -> 46186 | B19: =B18+1 -> 6465 | C19: =SIN((2*PI()*A19-B19)/$D$2) -> 0.80687719 | D19: =SIN((2*PI()*A19-B19)/$D$3) -> -0.99989914 | E19: =SIN((2*PI()*A19-B19)/$D$4) -> 0.60864165
... A38: =A37+1 -> 46205 | B38: =B37+1 -> 6484 | C38: =SIN((2*PI()*A38-B38)/$D$2) -> 0.2801318 | D38: =SIN((2*PI()*A38-B38)/$D$3) -> 0.89710265 | E38: =SIN((2*PI()*A38-B38)/$D$4) -> -0.68463746

Sheet Ну и погода
A1: Колличество осадков(мм)
B2: 2019 | C2: 2020 | D2: 2021 | G2: максимальное количество осадков за 3 года (мм) | H2: =MAX(B3:D14) -> 116.7
A3: январь | B3: 52.8 | C3: 41.4 | D3: 57.1 | G3: минимальное количество осадков за 3 года (мм) | H3: =MIN(B3:D14) -> 0
A4: февраль | B4: 27.5 | C4: 33.7 | D4: 59.5 | G4: суммарное количество осадков за 3 года (мм) | H4: =SUM(B3:D14) -> 1438.5
A5: март | B5: 36.6 | C5: 33.7 | D5: 26.7 | G5: среднемесячное количество осадков за 3 года (мм) | H5: =AVERAGE(B3:D14) -> 39.958333
A6: апрель | B6: 4.6 | C6: 16.4 | D6: 77.2 | G6: количество засушливых месяцев за 3 года | H6: =COUNTIF(B3:D14,"<15") -> 6
A7: май | B7: 33.5 | C7: 106.5 | D7: 77.4
A8: июнь | B8: 46 | C8: 64.9 | D8: 55.5
A9: июль | B9: 42 | C9: 116.7 | D9: 37.4
A10: август | B10: 38.1 | C10: 27.1 | D10: 83.7
A11: сентябрь | B11: 14.2 | C11: 62.5 | D11: 3.4
A12: октябрь | B12: 46 | C12: 22.4 | D12: 0
A13: ноябрь | B13: 15.6 | C13: 36.7 | D13: 0
A14: декабрь | B14: 22 | C14: 19.7 | D14: 0
A16: Данные за 2021 | C16: прогноз
A17: =A3 -> январь | B17: =D3 -> 57.1 | C17: =IF(B17<15,"засуха",IF(B17>70,"дождливо","нормально")) -> нормально
A18: =A4 -> февраль | B18: =D4 -> 59.5 | C18: =IF(B18<15,"засуха",IF(B18>70,"дождливо","нормально")) -> нормально
A19: =A5 -> март | B19: =D5 -> 26.7 | C19: =IF(B19<15,"засуха",IF(B19>70,"дождливо","нормально")) -> нормально
A20: =A6 -> апрель | B20: =D6 -> 77.2 | C20: =IF(B20<15,"засуха",IF(B20>70,"дождливо","нормально")) -> дождливо
A21: =A7 -> май | B21: =D7 -> 77.4 | C21: =IF(B21<15,"засуха",IF(B21>70,"дождливо","нормально")) -> дождливо
A22: =A8 -> июнь | B22: =D8 -> 55.5 | C22: =IF(B22<15,"засуха",IF(B22>70,"дождливо","нормально")) -> нормально
A23: =A9 -> июль | B23: =D9 -> 37.4 | C23: =IF(B23<15,"засуха",IF(B23>70,"дождливо","нормально")) -> нормально
A24: =A10 -> август | B24: =D10 -> 83.7 | C24: =IF(B24<15,"засуха",IF(B24>70,"дождливо","нормально")) -> дождливо
A25: =A11 -> сентябрь | B25: =D11 -> 3.4 | C25: =IF(B25<15,"засуха",IF(B25>70,"дождливо","нормально")) -> засуха
A26: =A12 -> октябрь | B26: =D12 -> 0 | C26: =IF(B26<15,"засуха",IF(B26>70,"дождливо","нормально")) -> засуха
A27: =A13 -> ноябрь | B27: =D13 -> 0 | C27: =IF(B27<15,"засуха",IF(B27>70,"дождливо","нормально")) -> засуха
A28: =A14 -> декабрь | B28: =D14 -> 0 | C28: =IF(B28<15,"засуха",IF(B28>70,"дождливо","нормально")) -> засуха
A30: максимальное кол-во осадков | B30: =MAX(B17:B28) -> 83.7
A31: минимальное кол-во осадков | B31: =MIN(B17:B28) -> 0
A32: суммарное кол-во осадков | B32: =SUM(B17:B28) -> 477.9
A33: среднемесячное кол-во осадков | B33: =AVERAGE(B17:B28) -> 39.825
A34: кол-во эасушливых месяцев | B34: =COUNTIF(B17:B28,"<15") -> 4

Sheet Магазин
A1: ДОХОД ОТ ПРОДАЖ ЗА 1 ПОЛУГОДИЕ (В ДОЛЛАРАХ США)
A2: Статья дохода | B2: январь | C2: февраль | D2: март | E2: апрель | F2: май | G2: июнь | H2: в среденем
A3: аудиосистемы | B3: 95780 | C3: 86982 | D3: 91653 | E3: 95780 | F3: 88440 | G3: 85700 | H3: =AVERAGE(B3:G3) -> 90722.5
A4: видеосистемы | B4: 77894 | C4: 84560 | D4: 80080 | E4: 81200 | F4: 80150 | G4: 91400 | H4: =AVERAGE(B4:G4) -> 82547.333
A5: оргтехника | B5: 34600 | C5: 42567 | D5: 40870 | E5: 39845 | F5: 40500 | G5: 43800 | H5: =AVERAGE(B5:G5) -> 40363.667
A6: компьютеры | B6: 40000 | C6: 35000 | D6: 44000 | E6: 42350 | F6: 27500 | G6: 39800 | H6: =AVERAGE(B6:G6) -> 38108.333

Sheet Зарплата
A1: № п/п | B1: Ф. И. О. | C1: Таб. номер | D1: Отдел | E1: Должность | F1: Начислено | G1: Удержано | H1: К выдаче
A2: 6 | B2: Сидоров П. П. | C2: 11014 | D2: 1 | E2: Зам. директора | F2: 7600 | G2: =F2*0.14 -> 1064 | H2: =F2-G2 -> 6536
A3: 2 | B3: Сидоров Б. В. | C3: 11028 | D3: 1 | E3: Бугалтер | F3: 4500 | G3: =F3*0.14 -> 630 | H3: =F3-G3 -> 3870
A4: 8 | B4: Протасов И. А. | C4: 11019 | D4: 1 | E4: Нач. отдела | F4: 6450 | G4: =F4*0.14 -> 903 | H4: =F4-G4 -> 5547
A5: 13 | B5: Осина Л. Д. | C5: 11045 | D5: 1 | E5: Референт | F5: 2800 | G5: =F5*0.14 -> 392 | H5: =F5-G5 -> 2408
A6: 14 | B6: Львов О. И. | C6: 11023 | D6: 1 | E6: Ст. бухгалтер | F6: 7200 | G6: =F6*0.14 -> 1008 | H6: =F6-G6 -> 6192
A7: 17 | B7: Бондаренко А. А. | C7: 11009 | D7: 1 | E7: Директор | F7: 9850 | G7: =F7*0.14 -> 1379 | H7: =F7-G7 -> 8471
A8: 4 | B8: Алексеев Р. П. | C8: 11036 | D8: 1 | E8: Бухгалтер | F8: 4450 | G8: =F8*0.14 -> 623 | H8: =F8-G8 -> 3827
A9: 18 | B9: Алексеев И. В. | C9: 11003 | D9: 1 | E9: Гл. бухгалтер | F9: 7800 | G9: =F9*0.14 -> 1092 | H9: =F9-G9 -> 6708
A10: 7 | B10: Сажин Р. О. | C10: 11025 | D10: 2 | E10: Зам. директора | F10: 7480 | G10: =F10*0.14 -> 1047.2 | H10: =F10-G10 -> 6432.8
A11: 10 | B11: Пинчук И. И. | C11: 11033 | D11: 2 | E11: Инженер | F11: 3460 | G11: =F11*0.14 -> 484.4 | H11: =F11-G11 -> 2975.6
A12: 3 | B12: Петров П. П. | C12: 11044 | D12: 2 | E12: Ст. инженер | F12: 4200 | G12: =F12*0.14 -> 588 | H12: =F12-G12 -> 3612
A13: 9 | B13: Петров П. И. | C13: 11018 | D13: 2 | E13: Нач. отдела | F13: 6840 | G13: =F13*0.14 -> 957.6 | H13: =F13-G13 -> 5882.4
... A19: 15 | B19: Козлов Е. И. | C19: 11010 | D19: 3 | E19: Инженер | F19: 3600 | G19: =F19*0.14 -> 504 | H19: =F19-G19 -> 3096
A22: № п/п | B22: Ф. И. О. | C22: Таб. номер | D22: Отдел | E22: Должность | F22: Начислено | G22: Удержано | H22: К выдаче
A23: 1 | B23: Ли А. А. | C23: 11043 | D23: 3 | E23: Иженер | F23: 3850 | G23: 539 | H23: 3311
A24: 10 | B24: Пинчук И. И. | C24: 11033 | D24: 2 | E24: Инженер | F24: 3460 | G24: 484.4 | H24: 2975.6
A25: 11 | B25: Пилипенко Ю. Д. | C25: 11012 | D25: 3 | E25: Инженер | F25: 3950 | G25: 553 | H25: 3397
A26: 12 | B26: Петров С. В. | C26: 11022 | D26: 3 | E26: Инженер | F26: 3740 | G26: 523.6 | H26: 3216.4
A27: 13 | B27: Осина Л. Д. | C27: 11045 | D27: 1 | E27: Референт | F27: 2800 | G27: 392 | H27: 2408
A28: 15 | B28: Козлов Е. И. | C28: 11010 | D28: 3 | E28: Инженер | F28: 3600 | G28: 504 | H28: 3096
A30: № п/п | B30: Ф. И. О. | C30: Таб. номер | D30: Отдел | E30: Должность | F30: Начислено | G30: Удержано | H30: К выдаче
A31: 2 | B31: Сидоров Б. В. | C31: 11028 | D31: 1 | E31: Бугалтер | F31: 4500 | G31: 630 | H31: 3870
A32: 4 | B32: Алексеев Р. П. | C32: 11036 | D32: 1 | E32: Бухгалтер | F32: 4450 | G32: 623 | H32: 3827
A33: 6 | B33: Сидоров П. П. | C33: 11014 | D33: 1 | E33: Зам. директора | F33: 7600 | G33: 1064 | H33: 6536
A34: 8 | B34: Протасов И. А. | C34: 11019 | D34: 1 | E34: Нач. отдела | F34: 6450 | G34: 903 | H34: 5547
A35: 13 | B35: Осина Л. Д. | C35: 11045 | D35: 1 | E35: Референт | F35: 2800 | G35: 392 | H35: 2408
A36: 14 | B36: Львов О. И. | C36: 11023 | D36: 1 | E36: Ст. бухгалтер | F36: 7200 | G36: 1008 | H36: 6192
A37: 17 | B37: Бондаренко А. А. | C37: 11009 | D37: 1 | E37: Директор | F37: 9850 | G37: 1379 | H37: 8471
A38: 18 | B38: Алексеев И. В. | C38: 11003 | D38: 1 | E38: Гл. бухгалтер | F38: 7800 | G38: 1092 | H38: 6708
A40: № п/п | B40: Ф. И. О. | C40: Таб. номер | D40: Отдел | E40: Должность | F40: Начислено | G40: Удержано | H40: К выдаче
A41: 3 | B41: Петров П. П. | C41: 11044 | D41: 2 | E41: Ст. инженер | F41: 4200 | G41: 588 | H41: 3612
A42: 7 | B42: Сажин Р. О. | C42: 11025 | D42: 2 | E42: Зам. директора | F42: 7480 | G42: 1047.2 | H42: 6432.8
A43: 9 | B43: Петров П. И. | C43: 11018 | D43: 2 | E43: Нач. отдела | F43: 6840 | G43: 957.6 | H43: 5882.4
A44: 10 | B44: Пинчук И. И. | C44: 11033 | D44: 2 | E44: Инженер | F44: 3460 | G44: 484.4 | H44: 2975.6
A45: 16 | B45: Кириллов А. П. | C45: 11002 | D45: 2 | E45: Cт. инженер | F45: 4100 | G45: 574 | H45: 3526
A47: № п/п | B47: Ф. И. О. | C47: Таб. номер | D47: Отдел | E47: Должность | F47: Начислено | G47: Удержано | H47: К выдаче
A48: 10 | B48: Пинчук И. И. | C48: 11033 | D48: 2 | E48: Инженер | F48: 3460 | G48: 484.4 | H48: 2975.6
A49: 11 | B49: Пилипенко Ю. Д. | C49: 11012 | D49: 3 | E49: Инженер | F49: 3950 | G49: 553 | H49: 3397
A50: 12 | B50: Петров С. В. | C50: 11022 | D50: 3 | E50: Инженер | F50: 3740 | G50: 523.6 | H50: 3216.4

Sheet Сортировка
A1: Сортировка Отдел, Ф.И.О. по возрастанию.
A2: № п/п | B2: Ф. И. О. | C2: Таб. номер | D2: Отдел | E2: Должность | F2: Начислено | G2: Удержано | H2: К выдаче
A3: 18 | B3: Алексеев И. В. | C3: 11003 | D3: 1 | E3: Гл. бухгалтер | F3: 7800 | G3: =F3*0.14 -> 1092 | H3: =F3-G3 -> 6708
A4: 4 | B4: Алексеев Р. П. | C4: 11036 | D4: 1 | E4: Бухгалтер | F4: 4450 | G4: =F4*0.14 -> 623 | H4: =F4-G4 -> 3827
A5: 17 | B5: Бондаренко А. А. | C5: 11009 | D5: 1 | E5: Директор | F5: 9850 | G5: =F5*0.14 -> 1379 | H5: =F5-G5 -> 8471
A6: 16 | B6: Кириллов А. П. | C6: 11002 | D6: 2 | E6: Cт. инженер | F6: 4100 | G6: =F6*0.14 -> 574 | H6: =F6-G6 -> 3526
A7: 15 | B7: Козлов Е. И. | C7: 11010 | D7: 3 | E7: Инженер | F7: 3600 | G7: =F7*0.14 -> 504 | H7: =F7-G7 -> 3096
A8: 1 | B8: Ли А. А. | C8: 11043 | D8: 3 | E8: Иженер | F8: 3850 | G8: =F8*0.14 -> 539 | H8: =F8-G8 -> 3311
A9: 14 | B9: Львов О. И. | C9: 11023 | D9: 1 | E9: Ст. бухгалтер | F9: 7200 | G9: =F9*0.14 -> 1008 | H9: =F9-G9 -> 6192
A10: 13 | B10: Осина Л. Д. | C10: 11045 | D10: 1 | E10: Референт | F10: 2800 | G10: =F10*0.14 -> 392 | H10: =F10-G10 -> 2408
A11: 9 | B11: Петров П. И. | C11: 11018 | D11: 2 | E11: Нач. отдела | F11: 6840 | G11: =F11*0.14 -> 957.6 | H11: =F11-G11 -> 5882.4
A12: 3 | B12: Петров П. П. | C12: 11044 | D12: 2 | E12: Ст. инженер | F12: 4200 | G12: =F12*0.14 -> 588 | H12: =F12-G12 -> 3612
A13: 12 | B13: Петров С. В. | C13: 11022 | D13: 3 | E13: Инженер | F13: 3740 | G13: =F13*0.14 -> 523.6 | H13: =F13-G13 -> 3216.4
A14: 11 | B14: Пилипенко Ю. Д. | C14: 11012 | D14: 3 | E14: Инженер | F14: 3950 | G14: =F14*0.14 -> 553 | H14: =F14-G14 -> 3397
... A20: 5 | B20: Штагер Е. А. | C20: 11017 | D20: 3 | E20: Нач. отдела | F20: 6299 | G20: =F20*0.14 -> 881.86 | H20: =F20-G20 -> 5417.14
A22: Сортировка Отдел, Начислено по убыванию.
A23: № п/п | B23: Ф. И. О. | C23: Таб. номер | D23: Отдел | E23: Должность | F23: Начислено | G23: Удержано | H23: К выдаче
A24: 5 | B24: Штагер Е. А. | C24: 11017 | D24: 3 | E24: Нач. отдела | F24: 6299 | G24: =F24*0.14 -> 881.86 | H24: =F24-G24 -> 5417.14
A25: 11 | B25: Пилипенко Ю. Д. | C25: 11012 | D25: 3 | E25: Инженер | F25: 3950 | G25: =F25*0.14 -> 553 | H25: =F25-G25 -> 3397
A26: 1 | B26: Ли А. А. | C26: 11043 | D26: 3 | E26: Иженер | F26: 3850 | G26: =F26*0.14 -> 539 | H26: =F26-G26 -> 3311
A27: 12 | B27: Петров С. В. | C27: 11022 | D27: 3 | E27: Инженер | F27: 3740 | G27: =F27*0.14 -> 523.6 | H27: =F27-G27 -> 3216.4
A28: 15 | B28: Козлов Е. И. | C28: 11010 | D28: 3 | E28: Инженер | F28: 3600 | G28: =F28*0.14 -> 504 | H28: =F28-G28 -> 3096
A29: 7 | B29: Сажин Р. О. | C29: 11025 | D29: 2 | E29: Зам. директора | F29: 7480 | G29: =F29*0.14 -> 1047.2 | H29: =F29-G29 -> 6432.8
A30: 9 | B30: Петров П. И. | C30: 11018 | D30: 2 | E30: Нач. отдела | F30: 6840 | G30: =F30*0.14 -> 957.6 | H30: =F30-G30 -> 5882.4
A31: 3 | B31: Петров П. П. | C31: 11044 | D31: 2 | E31: Ст. инженер | F31: 4200 | G31: =F31*0.14 -> 588 | H31: =F31-G31 -> 3612
A32: 16 | B32: Кириллов А. П. | C32: 11002 | D32: 2 | E32: Cт. инженер | F32: 4100 | G32: =F32*0.14 -> 574 | H32: =F32-G32 -> 3526
A33: 10 | B33: Пинчук И. И. | C33: 11033 | D33: 2 | E33: Инженер | F33: 3460 | G33: =F33*0.14 -> 484.4 | H33: =F33-G33 -> 2975.6
A34: 17 | B34: Бондаренко А. А. | C34: 11009 | D34: 1 | E34: Директор | F34: 9850 | G34: =F34*0.14 -> 1379 | H34: =F34-G34 -> 8471
A35: 18 | B35: Алексеев И. В. | C35: 11003 | D35: 1 | E35: Гл. бухгалтер | F35: 7800 | G35: =F35*0.14 -> 1092 | H35: =F35-G35 -> 6708
... A41: 13 | B41: Осина Л. Д. | C41: 11045 | D41: 1 | E41: Референт | F41: 2800 | G41: =F41*0.14 -> 392 | H41: =F41-G41 -> 2408
A43: Сортировка Отдел, Должность, Ф.И.О.
A44: № п/п | B44: Ф. И. О. | C44: Таб. номер | D44: Отдел | E44: Должность | F44: Начислено | G44: Удержано | H44: К выдаче
A45: 18 | B45: Алексеев И. В. | C45: 11003 | D45: 1 | E45: Гл. бухгалтер | F45: 7800 | G45: =F45*0.14 -> 1092 | H45: =F45-G45 -> 6708
A46: 4 | B46: Алексеев Р. П. | C46: 11036 | D46: 1 | E46: Бухгалтер | F46: 4450 | G46: =F46*0.14 -> 623 | H46: =F46-G46 -> 3827
A47: 17 | B47: Бондаренко А. А. | C47: 11009 | D47: 1 | E47: Директор | F47: 9850 | G47: =F47*0.14 -> 1379 | H47: =F47-G47 -> 8471
A48: 16 | B48: Кириллов А. П. | C48: 11002 | D48: 2 | E48: Cт. инженер | F48: 4100 | G48: =F48*0.14 -> 574 | H48: =F48-G48 -> 3526
A49: 15 | B49: Козлов Е. И. | C49: 11010 | D49: 3 | E49: Инженер | F49: 3600 | G49: =F49*0.14 -> 504 | H49: =F49-G49 -> 3096
A50: 1 | B50: Ли А. А. | C50: 11043 | D50: 3 | E50: Иженер | F50: 3850 | G50: =F50*0.14 -> 539 | H50: =F50-G50 -> 3311
A51: 14 | B51: Львов О. И. | C51: 11023 | D51: 1 | E51: Ст. бухгалтер | F51: 7200 | G51: =F51*0.14 -> 1008 | H51: =F51-G51 -> 6192
A52: 13 | B52: Осина Л. Д. | C52: 11045 | D52: 1 | E52: Референт | F52: 2800 | G52: =F52*0.14 -> 392 | H52: =F52-G52 -> 2408
...

Sheet Склад
A1: Склад
A2: Продукты | B2: Цена | C2: Количество | D2: Сумма | E2: Срок реализации | F2: Истек
A3: Баунти | B3: 8.5 | C3: 500 | D3: =B3*C3 -> 4250 | E3: 46169 | F3: =IF(E3<TODAY(),"просроченно","не просроченно") -> просроченно
A4: Зефир | B4: 31.2 | C4: 270 | D4: =B4*C4 -> 8424 | E4: 46171 | F4: =IF(E4<TODAY(),"просроченно","не просроченно") -> просроченно
A5: Мармелад | B5: 12.3 | C5: 35 | D5: =B5*C5 -> 430.5 | E5: 46165 | F5: =IF(E5<TODAY(),"просроченно","не просроченно") -> просроченно
A6: Марс | B6: 8.5 | C6: 125 | D6: =B6*C6 -> 1062.5 | E6: 46163 | F6: =IF(E6<TODAY(),"просроченно","не просроченно") -> просроченно
A7: Пастила | B7: 24.5 | C7: 450 | D7: =B7*C7 -> 11025 | E7: 46168 | F7: =IF(E7<TODAY(),"просроченно","не просроченно") -> просроченно
A8: Рондо | B8: 7.6 | C8: 320 | D8: =B8*C8 -> 2432 | E8: 46166 | F8: =IF(E8<TODAY(),"просроченно","не просроченно") -> просроченно
A9: Сникерс | B9: 8.5 | C9: 240 | D9: =B9*C9 -> 2040 | E9: 46164 | F9: =IF(E9<TODAY(),"просроченно","не просроченно") -> просроченно
A10: Сникерс | B10: 6.3 | C10: 610 | D10: =B10*C10 -> 3843 | E10: 46172 | F10: =IF(E10<TODAY(),"просроченно","не просроченно") -> просроченно
A11: Твикс | B11: 7.8 | C11: 450 | D11: =B11*C11 -> 3510 | E11: 46167 | F11: =IF(E11<TODAY(),"просроченно","не просроченно") -> просроченно
A12: Шок | B12: 8 | C12: 370 | D12: =B12*C12 -> 2960 | E12: 46170 | F12: =IF(E12<TODAY(),"просроченно","не просроченно") -> просроченно

Sheet Сортировка2
A1: Продукты | B1: Цена | C1: Количество | D1: Сумма | E1: Срок реализации | F1: Истек
A2: Баунти | B2: 8.5 | C2: 500 | D2: =B2*C2 -> 4250 | E2: 46169 | F2: =IF(E2<TODAY(),"просроченно","не просроченно") -> просроченно
A3: Зефир | B3: 31.2 | C3: 270 | D3: =B3*C3 -> 8424 | E3: 46171 | F3: =IF(E3<TODAY(),"просроченно","не просроченно") -> просроченно
A4: Мармелад | B4: 12.3 | C4: 35 | D4: =B4*C4 -> 430.5 | E4: 46165 | F4: =IF(E4<TODAY(),"просроченно","не просроченно") -> просроченно
A5: Марс | B5: 8.5 | C5: 125 | D5: =B5*C5 -> 1062.5 | E5: 46163 | F5: =IF(E5<TODAY(),"просроченно","не просроченно") -> просроченно
A6: Пастила | B6: 24.5 | C6: 450 | D6: =B6*C6 -> 11025 | E6: 46168 | F6: =IF(E6<TODAY(),"просроченно","не просроченно") -> просроченно
A7: Рондо | B7: 7.6 | C7: 320 | D7: =B7*C7 -> 2432 | E7: 46166 | F7: =IF(E7<TODAY(),"просроченно","не просроченно") -> просроченно
A8: Сникерс | B8: 8.5 | C8: 240 | D8: =B8*C8 -> 2040 | E8: 46164 | F8: =IF(E8<TODAY(),"просроченно","не просроченно") -> просроченно
A9: Сникерс | B9: 6.3 | C9: 610 | D9: =B9*C9 -> 3843 | E9: 46172 | F9: =IF(E9<TODAY(),"просроченно","не просроченно") -> просроченно
A10: Твикс | B10: 7.8 | C10: 450 | D10: =B10*C10 -> 3510 | E10: 46167 | F10: =IF(E10<TODAY(),"просроченно","не просроченно") -> просроченно
A11: Шок | B11: 8 | C11: 370 | D11: =B11*C11 -> 2960 | E11: 46170 | F11: =IF(E11<TODAY(),"просроченно","не просроченно") -> просроченно

Sheet Поиск
A1: все продукты с истекшим сроком реализации | H1: все продукты, количество которых больше 300, а срок реализации еще не истек
A2: Продукты | B2: Цена | C2: Количество | D2: Сумма | E2: Срок реализации | F2: Истек | H2: Продукты | I2: Цена | J2: Количество | K2: Сумма | L2: Срок реализации | M2: Истек
A3: Мармелад | B3: 12.3 | C3: 35 | D3: 430.5 | E3: 46165 | F3: просроченно | H3: Баунти | I3: 8.5 | J3: 500 | K3: 4250 | L3: 46169 | M3: не просроченно
A4: Марс | B4: 8.5 | C4: 125 | D4: 1062.5 | E4: 46163 | F4: просроченно | H4: Пастила | I4: 24.5 | J4: 450 | K4: 11025 | L4: 46168 | M4: не просроченно
A5: Рондо | B5: 7.6 | C5: 320 | D5: 2432 | E5: 46166 | F5: просроченно | H5: Сникерс | I5: 6.3 | J5: 610 | K5: 3843 | L5: 46172 | M5: не просроченно
A6: Сникерс | B6: 8.5 | C6: 240 | D6: 2040 | E6: 46164 | F6: просроченно | H6: Твикс | I6: 7.8 | J6: 450 | K6: 3510 | L6: 46167 | M6: не просроченно
H7: Шок | I7: 8 | J7: 370 | K7: 2960 | L7: 46170 | M7: не просроченно
A8: все продукты, для которых общая сумма не меньше 300 р. и не больше 1000 р.
A9: Продукты | B9: Цена | C9: Количество | D9: Сумма | E9: Срок реализации | F9: Истек | H9: Все продукты сумма которых меньше 4000, и срок реализации истёк.
A10: Мармелад | B10: 12.3 | C10: 35 | D10: 430.5 | E10: 46165 | F10: просроченно | H10: Продукты | I10: Цена | J10: Количество | K10: Сумма | L10: Срок реализации | M10: Истек
H11: Мармелад | I11: 12.3 | J11: 35 | K11: 430.5 | L11: 46165 | M11: просроченно
H12: Марс | I12: 8.5 | J12: 125 | K12: 1062.5 | L12: 46163 | M12: просроченно
H13: Рондо | I13: 7.6 | J13: 320 | K13: 2432 | L13: 46166 | M13: просроченно
H14: Сникерс | I14: 8.5 | J14: 240 | K14: 2040 | L14: 46164 | M14: просроченно

Sheet Больница
A1: коэф. | B1: коэф. | C1: Должность | D1: зарплата сотрудников | E1: кол-во сотрудников | F1: сумм. з/плата | H1: з/пл. | L1: Варианты штатного рассписания
A2: А | B2: В | H2: санитарки | L2: Вариант | M2: Должность | N2: Количество сотр. | O2: з/пл. санитарки
A3: 1 | B3: 0 | C3: санитарка | D3: =H3 -> 151.29771 | E3: 5 | F3: =D3*E3 -> 756.48855 | H3: 151.29771 | L3: 1 | M3: санитарка | N3: 5 | O3: =H3 -> 151.29771
A4: 1.5 | B4: 0 | C4: медсестра | D4: =$H$3*A4+B4 -> 226.94656 | E4: 8 | F4: =D4*E4 -> 1815.5725 | M4: медсестра | N4: 8
A5: 3 | B5: 0 | C5: врач | D5: =$H$3*A5+B5 -> 453.89313 | E5: 10 | F5: =D5*E5 -> 4538.9313 | M5: врач | N5: 10
A6: 3 | B6: 30 | C6: зав. отд. | D6: =$H$3*A6+B6 -> 483.89313 | E6: 1 | F6: =D6*E6 -> 483.89313 | L6: 2 | M6: санитарка | N6: 6 | O6: =H16 -> 12.608142
A7: 2 | B7: 0 | C7: зав. аптекой | D7: =$H$3*A7+B7 -> 302.59542 | E7: 3 | F7: =D7*E7 -> 907.78626 | M7: медсестра | N7: 9
A8: 1.5 | B8: 40 | C8: завхоз | D8: =$H$3*A8+B8 -> 266.94656 | E8: 1 | F8: =D8*E8 -> 266.94656 | M8: врач | N8: 11
A9: 4 | B9: 0 | C9: глав. Врач. | D9: =$H$3*A9+B9 -> 605.19084 | E9: 1 | F9: =D9*E9 -> 605.19084 | L9: 3 | M9: санитарка | N9: 7 | O9: =H29 -> -86.455834
A10: 4 | B10: 20 | C10: зав. Больницей. | D10: =$H$3*A10+B10 -> 625.19084 | E10: 1 | F10: =D10*E10 -> 625.19084 | M10: медсестра | N10: 10
M11: врач | N11: 12
C12: суммарный месячный фондз/пл | D12: =SUM(D3:D10) -> 3115.9542 | F12: =SUM(F3:F10) -> 10000 | L12: 4 | M12: санитарка | N12: 7 | O12: =H42 -> -21.613959
M13: медсестра | N13: 10
A14: коэф. | B14: коэф. | C14: Должность | D14: зарплата сотрудников | E14: кол-во сотрудников | F14: сумм. з/плата | H14: з/пл. | M14: врач | N14: 11
A15: А | B15: В | H15: санитарки
A16: 1 | B16: 0 | C16: санитарка | D16: =H16 -> 12.608142 | E16: 6 | F16: =D16*E16 -> 75.648855 | H16: 12.608142
A17: 1.5 | B17: 0 | C17: медсестра | D17: =$H$3*A17+B17 -> 226.94656 | E17: 9 | F17: =D17*E17 -> 2042.5191
A18: 3 | B18: 0 | C18: врач | D18: =$H$3*A18+B18 -> 453.89313 | E18: 11 | F18: =D18*E18 -> 4992.8244
A19: 3 | B19: 30 | C19: зав. отд. | D19: =$H$3*A19+B19 -> 483.89313 | E19: 1 | F19: =D19*E19 -> 483.89313
A20: 2 | B20: 0 | C20: зав. аптекой | D20: =$H$3*A20+B20 -> 302.59542 | E20: 3 | F20: =D20*E20 -> 907.78626
A21: 1.5 | B21: 40 | C21: завхоз | D21: =$H$3*A21+B21 -> 266.94656 | E21: 1 | F21: =D21*E21 -> 266.94656
A22: 4 | B22: 0 | C22: глав. Врач. | D22: =$H$3*A22+B22 -> 605.19084 | E22: 1 | F22: =D22*E22 -> 605.19084
A23: 4 | B23: 20 | C23: зав. Больницей. | D23: =$H$3*A23+B23 -> 625.19084 | E23: 1 | F23: =D23*E23 -> 625.19084
C25: суммарный месячный фондз/пл | D25: =SUM(D16:D23) -> 2977.2646 | F25: =SUM(F16:F23) -> 10000
A27: коэф. | B27: коэф. | C27: Должность | D27: зарплата сотрудников | E27: кол-во сотрудников | F27: сумм. з/плата | H27: з/пл.
A28: А | B28: В | H28: санитарки
A29: 1 | B29: 0 | C29: санитарка | D29: =H29 -> -86.455834 | E29: 7 | F29: =D29*E29 -> -605.19084 | H29: -86.455834
A30: 1.5 | B30: 0 | C30: медсестра | D30: =$H$3*A30+B30 -> 226.94656 | E30: 10 | F30: =D30*E30 -> 2269.4656
A31: 3 | B31: 0 | C31: врач | D31: =$H$3*A31+B31 -> 453.89313 | E31: 12 | F31: =D31*E31 -> 5446.7176
A32: 3 | B32: 30 | C32: зав. отд. | D32: =$H$3*A32+B32 -> 483.89313 | E32: 1 | F32: =D32*E32 -> 483.89313
A33: 2 | B33: 0 | C33: зав. аптекой | D33: =$H$3*A33+B33 -> 302.59542 | E33: 3 | F33: =D33*E33 -> 907.78626
A34: 1.5 | B34: 40 | C34: завхоз | D34: =$H$3*A34+B34 -> 266.94656 | E34: 1 | F34: =D34*E34 -> 266.94656
A35: 4 | B35: 0 | C35: глав. Врач. | D35: =$H$3*A35+B35 -> 605.19084 | E35: 1 | F35: =D35*E35 -> 605.19084
A36: 4 | B36: 20 | C36: зав. Больницей. | D36: =$H$3*A36+B36 -> 625.19084 | E36: 1 | F36: =D36*E36 -> 625.19084
C38: суммарный месячный фондз/пл | D38: =SUM(D29:D36) -> 2878.2007 | F38: =SUM(F29:F36) -> 10000
A40: коэф. | B40: коэф. | C40: Должность | D40: зарплата сотрудников | E40: кол-во сотрудников | F40: сумм. з/плата | H40: з/пл.
A41: А | B41: В | H41: санитарки
A42: 1 | B42: 0 | C42: санитарка | D42: =H42 -> -21.613959 | E42: 7 | F42: =D42*E42 -> -151.29771 | H42: -21.613959
A43: 1.5 | B43: 0 | C43: медсестра | D43: =$H$3*A43+B43 -> 226.94656 | E43: 10 | F43: =D43*E43 -> 2269.4656
A44: 3 | B44: 0 | C44: врач | D44: =$H$3*A44+B44 -> 453.89313 | E44: 11 | F44: =D44*E44 -> 4992.8244
...
